Workbook

Sheet Diretoria
A1: GP2T · GESTÃO DE FROTA
A2: Relatório da Diretoria — os números vêm do aplicativo, sem digitação.
A3: ⚠️ Este arquivo está com DADOS DE EXEMPLO (linhas com _id começando em EX-). Apague-as quando os dados reais entrarem.
A4: Período de: | B4: 46235 | C4: até: | D4: 46295 | E4: Meta L/h: | F4: 20 | G4: Meta km/L: | H4: 1
A5: As células amarelas são as únicas que você edita nesta aba.
A6: RESULTADO DO PERÍODO | D6: A FROTA
A7: Consumo total | B7: =SUMIFS('Resumo por Dia'!$D$4:$D$3000,'Resumo por Dia'!$A$4:$A$3000,">="&Diretoria!$B$4,'Resumo por Dia'!$A$4:$A$3000,"<="&Diretoria!$D$4) | D7: Equipamentos que operaram | E7: =COUNTIF('Por Equipamento'!$D$4:$D$33,">0")
A8: Horas trabalhadas | B8: =SUMIFS('Resumo por Dia'!$E$4:$E$3000,'Resumo por Dia'!$A$4:$A$3000,">="&Diretoria!$B$4,'Resumo por Dia'!$A$4:$A$3000,"<="&Diretoria!$D$4) | D8: Operadores em atividade | E8: =COUNTIF('Por Operador'!$C$4:$C$33,">0")
A9: Produção movida | B9: =SUMIFS('Resumo por Dia'!$G$4:$G$3000,'Resumo por Dia'!$A$4:$A$3000,">="&Diretoria!$B$4,'Resumo por Dia'!$A$4:$A$3000,"<="&Diretoria!$D$4) | D9: Equipamentos cadastrados | E9: =COUNTA(Equipamentos!$A$4:$A$200)
A10: Viagens realizadas | B10: =SUMIFS('Resumo por Dia'!$N$4:$N$3000,'Resumo por Dia'!$A$4:$A$3000,">="&Diretoria!$B$4,'Resumo por Dia'!$A$4:$A$3000,"<="&Diretoria!$D$4) | D10: Disponibilidade da frota | E10: =IFERROR(COUNTIF(Equipamentos!$D$4:$D$200,"Operando")/COUNTA(Equipamentos!$A$4:$A$200),"—")
A11: Consumo por hora | B11: =IFERROR(B7/B8,"—") | D11: Manutenções no período | E11: =SUMIFS('Resumo por Dia'!$O$4:$O$3000,'Resumo por Dia'!$A$4:$A$3000,">="&Diretoria!$B$4,'Resumo por Dia'!$A$4:$A$3000,"<="&Diretoria!$D$4)
A12: Consumo por tonelada | B12: =IFERROR(B7/B9,"—") | D12: Acima da meta de L/h | E12: =COUNTIF('Por Equipamento'!$F$4:$F$33,">"&$F$4)
A13: Média da frota | B13: =IFERROR(SUMIFS('Resumo por Dia'!$L$4:$L$3000,'Resumo por Dia'!$A$4:$A$3000,">="&Diretoria!$B$4,'Resumo por Dia'!$A$4:$A$3000,"<="&Diretoria!$D$4)/B7,"—")
A14: Dias com operação | B14: =COUNTIFS('Resumo por Dia'!$A$4:$A$3000,">="&Diretoria!$B$4,'Resumo por Dia'!$A$4:$A$3000,"<="&Diretoria!$D$4)
A16: DESTAQUES
A17: Menor consumo por tonelada | B17: =IFERROR(INDEX('Por Equipamento'!$A$4:$A$33,MATCH(MIN('Por Equipamento'!$H$4:$H$33),'Por Equipamento'!$H$4:$H$33,0)),"—") | C17: =IFERROR(MIN('Por Equipamento'!$H$4:$H$33),"—")
A18: Maior consumo por tonelada | B18: =IFERROR(INDEX('Por Equipamento'!$A$4:$A$33,MATCH(MAX('Por Equipamento'!$H$4:$H$33),'Por Equipamento'!$H$4:$H$33,0)),"—") | C18: =IFERROR(MAX('Por Equipamento'!$H$4:$H$33),"—")
A19: Operador com mais produção | B19: =IFERROR(INDEX('Por Operador'!$A$4:$A$33,MATCH(MAX('Por Operador'!$F$4:$F$33),'Por Operador'!$F$4:$F$33,0)),"—") | C19: =IFERROR(MAX('Por Operador'!$F$4:$F$33),"—")
A20: Equipamento que mais consumiu | B20: =IFERROR(INDEX('Por Equipamento'!$A$4:$A$33,MATCH(MAX('Por Equipamento'!$D$4:$D$33),'Por Equipamento'!$D$4:$D$33,0)),"—") | C20: =IFERROR(MAX('Por Equipamento'!$D$4:$D$33),"—")
A23: COMO ESTA PLANILHA SE MANTÉM ATUALIZADA
A24: 1. Suba este arquivo no Google Drive e abra como Planilhas Google (o app não escreve em .xlsx).
A25: 2. No Apps Script do app, coloque o link desta planilha em PLANILHA_URL e faça Implantar → Nova versão.
A26: 3. No aplicativo: ⚙️ Configurações → 🔄 Sincronizar tudo.
A27: 4. Apague as linhas de exemplo (coluna _id começando com EX-) nas abas de dados.
A29: As abas cinzas (Resumo por Dia, Abastecimentos, Viagens…) são preenchidas pelo aplicativo a cada lançamento.
A30: As abas azuis são só apresentação: leem as abas cinzas e não recalculam nada por conta própria —
A31: por isso os números aqui são sempre iguais aos que aparecem no celular.

Sheet Por Equipamento
A1: DESEMPENHO POR EQUIPAMENTO
A2: Período definido na aba Diretoria. Fonte: aba Resumo por Equipamento (preenchida pelo app).
A3: Equipamento | B3: Tipo | C3: Dias operados | D3: Consumo (L) | E3: Horas | F3: L/h | G3: Produção (t) | H3: L/Ton | I3: KM rodado | J3: Média km/L | K3: Viagens
A4: =IF(Equipamentos!$A4="","",Equipamentos!$A4) | B4: =IF(Equipamentos!$A4="","",Equipamentos!$B4) | C4: =IF(Equipamentos!$A4="","",COUNTIFS('Resumo por Equipamento'!$B$4:$B$3000,$A4,'Resumo por Equipamento'!$A$4:$A$3000,">="&Diretoria!$B$4,'Resumo por Equipamento'!$A$4:$A$3000,"<="&Diretoria!$D$4,'Resumo por Equipamento'!$C$4:$C$3000,">0")) | D4: =IF(Equipamentos!$A4="","",SUMIFS('Resumo por Equipamento'!$C$4:$C$3000,'Resumo por Equipamento'!$B$4:$B$3000,$A4,'Resumo por Equipamento'!$A$4:$A$3000,">="&Diretoria!$B$4,'Resumo por Equipamento'!$A$4:$A$3000,"<="&Diretoria!$D$4)) | E4: =IF(Equipamentos!$A4="","",SUMIFS('Resumo por Equipamento'!$D$4:$D$3000,'Resumo por Equipamento'!$B$4:$B$3000,$A4,'Resumo por Equipamento'!$A$4:$A$3000,">="&Diretoria!$B$4,'Resumo por Equipamento'!$A$4:$A$3000,"<="&Diretoria!$D$4)) | F4: =IF(Equipamentos!$A4="","",IFERROR(IF(E4=0,"—",D4/E4),"—")) | G4: =IF(Equipamentos!$A4="","",SUMIFS('Resumo por Equipamento'!$F$4:$F$3000,'Resumo por Equipamento'!$B$4:$B$3000,$A4,'Resumo por Equipamento'!$A$4:$A$3000,">="&Diretoria!$B$4,'Resumo por Equipamento'!$A$4:$A$3000,"<="&Diretoria!$D$4)) | H4: =IF(Equipamentos!$A4="","",IFERROR(IF(G4=0,"—",D4/G4),"—")) | I4: =IF(Equipamentos!$A4="","",SUMIFS('Resumo por Equipamento'!$H$4:$H$3000,'Resumo por Equipamento'!$B$4:$B$3000,$A4,'Resumo por Equipamento'!$A$4:$A$3000,">="&Diretoria!$B$4,'Resumo por Equipamento'!$A$4:$A$3000,"<="&Diretoria!$D$4)) | J4: =IF(Equipamentos!$A4="","",IFERROR(IF(OR(D4=0,I4=0),"—",I4/D4),"—")) | K4: =IF(Equipamentos!$A4="","",SUMIFS('Resumo por Equipamento'!$J$4:$J$3000,'Resumo por Equipamento'!$B$4:$B$3000,$A4,'Resumo por Equipamento'!$A$4:$A$3000,">="&Diretoria!$B$4,'Resumo por Equipamento'!$A$4:$A$3000,"<="&Diretoria!$D$4))
A5: =IF(Equipamentos!$A5="","",Equipamentos!$A5) | B5: =IF(Equipamentos!$A5="","",Equipamentos!$B5) | C5: =IF(Equipamentos!$A5="","",COUNTIFS('Resumo por Equipamento'!$B$4:$B$3000,$A5,'Resumo por Equipamento'!$A$4:$A$3000,">="&Diretoria!$B$4,'Resumo por Equipamento'!$A$4:$A$3000,"<="&Diretoria!$D$4,'Resumo por Equipamento'!$C$4:$C$3000,">0")) | D5: =IF(Equipamentos!$A5="","",SUMIFS('Resumo por Equipamento'!$C$4:$C$3000,'Resumo por Equipamento'!$B$4:$B$3000,$A5,'Resumo por Equipamento'!$A$4:$A$3000,">="&Diretoria!$B$4,'Resumo por Equipamento'!$A$4:$A$3000,"<="&Diretoria!$D$4)) | E5: =IF(Equipamentos!$A5="","",SUMIFS('Resumo por Equipamento'!$D$4:$D$3000,'Resumo por Equipamento'!$B$4:$B$3000,$A5,'Resumo por Equipamento'!$A$4:$A$3000,">="&Diretoria!$B$4,'Resumo por Equipamento'!$A$4:$A$3000,"<="&Diretoria!$D$4)) | F5: =IF(Equipamentos!$A5="","",IFERROR(IF(E5=0,"—",D5/E5),"—")) | G5: =IF(Equipamentos!$A5="","",SUMIFS('Resumo por Equipamento'!$F$4:$F$3000,'Resumo por Equipamento'!$B$4:$B$3000,$A5,'Resumo por Equipamento'!$A$4:$A$3000,">="&Diretoria!$B$4,'Resumo por Equipamento'!$A$4:$A$3000,"<="&Diretoria!$D$4)) | H5: =IF(Equipamentos!$A5="","",IFERROR(IF(G5=0,"—",D5/G5),"—")) | I5: =IF(Equipamentos!$A5="","",SUMIFS('Resumo por Equipamento'!$H$4:$H$3000,'Resumo por Equipamento'!$B$4:$B$3000,$A5,'Resumo por Equipamento'!$A$4:$A$3000,">="&Diretoria!$B$4,'Resumo por Equipamento'!$A$4:$A$3000,"<="&Diretoria!$D$4)) | J5: =IF(Equipamentos!$A5="","",IFERROR(IF(OR(D5=0,I5=0),"—",I5/D5),"—")) | K5: =IF(Equipamentos!$A5="","",SUMIFS('Resumo por Equipamento'!$J$4:$J$3000,'Resumo por Equipamento'!$B$4:$B$3000,$A5,'Resumo por Equipamento'!$A$4:$A$3000,">="&Diretoria!$B$4,'Resumo por Equipamento'!$A$4:$A$3000,"<="&Diretoria!$D$4))
A6: =IF(Equipamentos!$A6="","",Equipamentos!$A6) | B6: =IF(Equipamentos!$A6="","",Equipamentos!$B6) | C6: =IF(Equipamentos!$A6="","",COUNTIFS('Resumo por Equipamento'!$B$4:$B$3000,$A6,'Resumo por Equipamento'!$A$4:$A$3000,">="&Diretoria!$B$4,'Resumo por Equipamento'!$A$4:$A$3000,"<="&Diretoria!$D$4,'Resumo por Equipamento'!$C$4:$C$3000,">0")) | D6: =IF(Equipamentos!$A6="","",SUMIFS('Resumo por Equipamento'!$C$4:$C$3000,'Resumo por Equipamento'!$B$4:$B$3000,$A6,'Resumo por Equipamento'!$A$4:$A$3000,">="&Diretoria!$B$4,'Resumo por Equipamento'!$A$4:$A$3000,"<="&Diretoria!$D$4)) | E6: =IF(Equipamentos!$A6="","",SUMIFS('Resumo por Equipamento'!$D$4:$D$3000,'Resumo por Equipamento'!$B$4:$B$3000,$A6,'Resumo por Equipamento'!$A$4:$A$3000,">="&Diretoria!$B$4,'Resumo por Equipamento'!$A$4:$A$3000,"<="&Diretoria!$D$4)) | F6: =IF(Equipamentos!$A6="","",IFERROR(IF(E6=0,"—",D6/E6),"—")) | G6: =IF(Equipamentos!$A6="","",SUMIFS('Resumo por Equipamento'!$F$4:$F$3000,'Resumo por Equipamento'!$B$4:$B$3000,$A6,'Resumo por Equipamento'!$A$4:$A$3000,">="&Diretoria!$B$4,'Resumo por Equipamento'!$A$4:$A$3000,"<="&Diretoria!$D$4)) | H6: =IF(Equipamentos!$A6="","",IFERROR(IF(G6=0,"—",D6/G6),"—")) | I6: =IF(Equipamentos!$A6="","",SUMIFS('Resumo por Equipamento'!$H$4:$H$3000,'Resumo por Equipamento'!$B$4:$B$3000,$A6,'Resumo por Equipamento'!$A$4:$A$3000,">="&Diretoria!$B$4,'Resumo por Equipamento'!$A$4:$A$3000,"<="&Diretoria!$D$4)) | J6: =IF(Equipamentos!$A6="","",IFERROR(IF(OR(D6=0,I6=0),"—",I6/D6),"—")) | K6: =IF(Equipamentos!$A6="","",SUMIFS('Resumo por Equipamento'!$J$4:$J$3000,'Resumo por Equipamento'!$B$4:$B$3000,$A6,'Resumo por Equipamento'!$A$4:$A$3000,">="&Diretoria!$B$4,'Resumo por Equipamento'!$A$4:$A$3000,"<="&Diretoria!$D$4))
A7: =IF(Equipamentos!$A7="","",Equipamentos!$A7) | B7: =IF(Equipamentos!$A7="","",Equipamentos!$B7) | C7: =IF(Equipamentos!$A7="","",COUNTIFS('Resumo por Equipamento'!$B$4:$B$3000,$A7,'Resumo por Equipamento'!$A$4:$A$3000,">="&Diretoria!$B$4,'Resumo por Equipamento'!$A$4:$A$3000,"<="&Diretoria!$D$4,'Resumo por Equipamento'!$C$4:$C$3000,">0")) | D7: =IF(Equipamentos!$A7="","",SUMIFS('Resumo por Equipamento'!$C$4:$C$3000,'Resumo por Equipamento'!$B$4:$B$3000,$A7,'Resumo por Equipamento'!$A$4:$A$3000,">="&Diretoria!$B$4,'Resumo por Equipamento'!$A$4:$A$3000,"<="&Diretoria!$D$4)) | E7: =IF(Equipamentos!$A7="","",SUMIFS('Resumo por Equipamento'!$D$4:$D$3000,'Resumo por Equipamento'!$B$4:$B$3000,$A7,'Resumo por Equipamento'!$A$4:$A$3000,">="&Diretoria!$B$4,'Resumo por Equipamento'!$A$4:$A$3000,"<="&Diretoria!$D$4)) | F7: =IF(Equipamentos!$A7="","",IFERROR(IF(E7=0,"—",D7/E7),"—")) | G7: =IF(Equipamentos!$A7="","",SUMIFS('Resumo por Equipamento'!$F$4:$F$3000,'Resumo por Equipamento'!$B$4:$B$3000,$A7,'Resumo por Equipamento'!$A$4:$A$3000,">="&Diretoria!$B$4,'Resumo por Equipamento'!$A$4:$A$3000,"<="&Diretoria!$D$4)) | H7: =IF(Equipamentos!$A7="","",IFERROR(IF(G7=0,"—",D7/G7),"—")) | I7: =IF(Equipamentos!$A7="","",SUMIFS('Resumo por Equipamento'!$H$4:$H$3000,'Resumo por Equipamento'!$B$4:$B$3000,$A7,'Resumo por Equipamento'!$A$4:$A$3000,">="&Diretoria!$B$4,'Resumo por Equipamento'!$A$4:$A$3000,"<="&Diretoria!$D$4)) | J7: =IF(Equipamentos!$A7="","",IFERROR(IF(OR(D7=0,I7=0),"—",I7/D7),"—")) | K7: =IF(Equipamentos!$A7="","",SUMIFS('Resumo por Equipamento'!$J$4:$J$3000,'Resumo por Equipamento'!$B$4:$B$3000,$A7,'Resumo por Equipamento'!$A$4:$A$3000,">="&Diretoria!$B$4,'Resumo por Equipamento'!$A$4:$A$3000,"<="&Diretoria!$D$4))
A8: =IF(Equipamentos!$A8="","",Equipamentos!$A8) | B8: =IF(Equipamentos!$A8="","",Equipamentos!$B8) | C8: =IF(Equipamentos!$A8="","",COUNTIFS('Resumo por Equipamento'!$B$4:$B$3000,$A8,'Resumo por Equipamento'!$A$4:$A$3000,">="&Diretoria!$B$4,'Resumo por Equipamento'!$A$4:$A$3000,"<="&Diretoria!$D$4,'Resumo por Equipamento'!$C$4:$C$3000,">0")) | D8: =IF(Equipamentos!$A8="","",SUMIFS('Resumo por Equipamento'!$C$4:$C$3000,'Resumo por Equipamento'!$B$4:$B$3000,$A8,'Resumo por Equipamento'!$A$4:$A$3000,">="&Diretoria!$B$4,'Resumo por Equipamento'!$A$4:$A$3000,"<="&Diretoria!$D$4)) | E8: =IF(Equipamentos!$A8="","",SUMIFS('Resumo por Equipamento'!$D$4:$D$3000,'Resumo por Equipamento'!$B$4:$B$3000,$A8,'Resumo por Equipamento'!$A$4:$A$3000,">="&Diretoria!$B$4,'Resumo por Equipamento'!$A$4:$A$3000,"<="&Diretoria!$D$4)) | F8: =IF(Equipamentos!$A8="","",IFERROR(IF(E8=0,"—",D8/E8),"—")) | G8: =IF(Equipamentos!$A8="","",SUMIFS('Resumo por Equipamento'!$F$4:$F$3000,'Resumo por Equipamento'!$B$4:$B$3000,$A8,'Resumo por Equipamento'!$A$4:$A$3000,">="&Diretoria!$B$4,'Resumo por Equipamento'!$A$4:$A$3000,"<="&Diretoria!$D$4)) | H8: =IF(Equipamentos!$A8="","",IFERROR(IF(G8=0,"—",D8/G8),"—")) | I8: =IF(Equipamentos!$A8="","",SUMIFS('Resumo por Equipamento'!$H$4:$H$3000,'Resumo por Equipamento'!$B$4:$B$3000,$A8,'Resumo por Equipamento'!$A$4:$A$3000,">="&Diretoria!$B$4,'Resumo por Equipamento'!$A$4:$A$3000,"<="&Diretoria!$D$4)) | J8: =IF(Equipamentos!$A8="","",IFERROR(IF(OR(D8=0,I8=0),"—",I8/D8),"—")) | K8: =IF(Equipamentos!$A8="","",SUMIFS('Resumo por Equipamento'!$J$4:$J$3000,'Resumo por Equipamento'!$B$4:$B$3000,$A8,'Resumo por Equipamento'!$A$4:$A$3000,">="&Diretoria!$B$4,'Resumo por Equipamento'!$A$4:$A$3000,"<="&Diretoria!$D$4))
A9: =IF(Equipamentos!$A9="","",Equipamentos!$A9) | B9: =IF(Equipamentos!$A9="","",Equipamentos!$B9) | C9: =IF(Equipamentos!$A9="","",COUNTIFS('Resumo por Equipamento'!$B$4:$B$3000,$A9,'Resumo por Equipamento'!$A$4:$A$3000,">="&Diretoria!$B$4,'Resumo por Equipamento'!$A$4:$A$3000,"<="&Diretoria!$D$4,'Resumo por Equipamento'!$C$4:$C$3000,">0")) | D9: =IF(Equipamentos!$A9="","",SUMIFS('Resumo por Equipamento'!$C$4:$C$3000,'Resumo por Equipamento'!$B$4:$B$3000,$A9,'Resumo por Equipamento'!$A$4:$A$3000,">="&Diretoria!$B$4,'Resumo por Equipamento'!$A$4:$A$3000,"<="&Diretoria!$D$4)) | E9: =IF(Equipamentos!$A9="","",SUMIFS('Resumo por Equipamento'!$D$4:$D$3000,'Resumo por Equipamento'!$B$4:$B$3000,$A9,'Resumo por Equipamento'!$A$4:$A$3000,">="&Diretoria!$B$4,'Resumo por Equipamento'!$A$4:$A$3000,"<="&Diretoria!$D$4)) | F9: =IF(Equipamentos!$A9="","",IFERROR(IF(E9=0,"—",D9/E9),"—")) | G9: =IF(Equipamentos!$A9="","",SUMIFS('Resumo por Equipamento'!$F$4:$F$3000,'Resumo por Equipamento'!$B$4:$B$3000,$A9,'Resumo por Equipamento'!$A$4:$A$3000,">="&Diretoria!$B$4,'Resumo por Equipamento'!$A$4:$A$3000,"<="&Diretoria!$D$4)) | H9: =IF(Equipamentos!$A9="","",IFERROR(IF(G9=0,"—",D9/G9),"—")) | I9: =IF(Equipamentos!$A9="","",SUMIFS('Resumo por Equipamento'!$H$4:$H$3000,'Resumo por Equipamento'!$B$4:$B$3000,$A9,'Resumo por Equipamento'!$A$4:$A$3000,">="&Diretoria!$B$4,'Resumo por Equipamento'!$A$4:$A$3000,"<="&Diretoria!$D$4)) | J9: =IF(Equipamentos!$A9="","",IFERROR(IF(OR(D9=0,I9=0),"—",I9/D9),"—")) | K9: =IF(Equipamentos!$A9="","",SUMIFS('Resumo por Equipamento'!$J$4:$J$3000,'Resumo por Equipamento'!$B$4:$B$3000,$A9,'Resumo por Equipamento'!$A$4:$A$3000,">="&Diretoria!$B$4,'Resumo por Equipamento'!$A$4:$A$3000,"<="&Diretoria!$D$4))
A10: =IF(Equipamentos!$A10="","",Equipamentos!$A10) | B10: =IF(Equipamentos!$A10="","",Equipamentos!$B10) | C10: =IF(Equipamentos!$A10="","",COUNTIFS('Resumo por Equipamento'!$B$4:$B$3000,$A10,'Resumo por Equipamento'!$A$4:$A$3000,">="&Diretoria!$B$4,'Resumo por Equipamento'!$A$4:$A$3000,"<="&Diretoria!$D$4,'Resumo por Equipamento'!$C$4:$C$3000,">0")) | D10: =IF(Equipamentos!$A10="","",SUMIFS('Resumo por Equipamento'!$C$4:$C$3000,'Resumo por Equipamento'!$B$4:$B$3000,$A10,'Resumo por Equipamento'!$A$4:$A$3000,">="&Diretoria!$B$4,'Resumo por Equipamento'!$A$4:$A$3000,"<="&Diretoria!$D$4)) | E10: =IF(Equipamentos!$A10="","",SUMIFS('Resumo por Equipamento'!$D$4:$D$3000,'Resumo por Equipamento'!$B$4:$B$3000,$A10,'Resumo por Equipamento'!$A$4:$A$3000,">="&Diretoria!$B$4,'Resumo por Equipamento'!$A$4:$A$3000,"<="&Diretoria!$D$4)) | F10: =IF(Equipamentos!$A10="","",IFERROR(IF(E10=0,"—",D10/E10),"—")) | G10: =IF(Equipamentos!$A10="","",SUMIFS('Resumo por Equipamento'!$F$4:$F$3000,'Resumo por Equipamento'!$B$4:$B$3000,$A10,'Resumo por Equipamento'!$A$4:$A$3000,">="&Diretoria!$B$4,'Resumo por Equipamento'!$A$4:$A$3000,"<="&Diretoria!$D$4)) | H10: =IF(Equipamentos!$A10="","",IFERROR(IF(G10=0,"—",D10/G10),"—")) | I10: =IF(Equipamentos!$A10="","",SUMIFS('Resumo por Equipamento'!$H$4:$H$3000,'Resumo por Equipamento'!$B$4:$B$3000,$A10,'Resumo por Equipamento'!$A$4:$A$3000,">="&Diretoria!$B$4,'Resumo por Equipamento'!$A$4:$A$3000,"<="&Diretoria!$D$4)) | J10: =IF(Equipamentos!$A10="","",IFERROR(IF(OR(D10=0,I10=0),"—",I10/D10),"—")) | K10: =IF(Equipamentos!$A10="","",SUMIFS('Resumo por Equipamento'!$J$4:$J$3000,'Resumo por Equipamento'!$B$4:$B$3000,$A10,'Resumo por Equipamento'!$A$4:$A$3000,">="&Diretoria!$B$4,'Resumo por Equipamento'!$A$4:$A$3000,"<="&Diretoria!$D$4))
A11: =IF(Equipamentos!$A11="","",Equipamentos!$A11) | B11: =IF(Equipamentos!$A11="","",Equipamentos!$B11) | C11: =IF(Equipamentos!$A11="","",COUNTIFS('Resumo por Equipamento'!$B$4:$B$3000,$A11,'Resumo por Equipamento'!$A$4:$A$3000,">="&Diretoria!$B$4,'Resumo por Equipamento'!$A$4:$A$3000,"<="&Diretoria!$D$4,'Resumo por Equipamento'!$C$4:$C$3000,">0")) | D11: =IF(Equipamentos!$A11="","",SUMIFS('Resumo por Equipamento'!$C$4:$C$3000,'Resumo por Equipamento'!$B$4:$B$3000,$A11,'Resumo por Equipamento'!$A$4:$A$3000,">="&Diretoria!$B$4,'Resumo por Equipamento'!$A$4:$A$3000,"<="&Diretoria!$D$4)) | E11: =IF(Equipamentos!$A11="","",SUMIFS('Resumo por Equipamento'!$D$4:$D$3000,'Resumo por Equipamento'!$B$4:$B$3000,$A11,'Resumo por Equipamento'!$A$4:$A$3000,">="&Diretoria!$B$4,'Resumo por Equipamento'!$A$4:$A$3000,"<="&Diretoria!$D$4)) | F11: =IF(Equipamentos!$A11="","",IFERROR(IF(E11=0,"—",D11/E11),"—")) | G11: =IF(Equipamentos!$A11="","",SUMIFS('Resumo por Equipamento'!$F$4:$F$3000,'Resumo por Equipamento'!$B$4:$B$3000,$A11,'Resumo por Equipamento'!$A$4:$A$3000,">="&Diretoria!$B$4,'Resumo por Equipamento'!$A$4:$A$3000,"<="&Diretoria!$D$4)) | H11: =IF(Equipamentos!$A11="","",IFERROR(IF(G11=0,"—",D11/G11),"—")) | I11: =IF(Equipamentos!$A11="","",SUMIFS('Resumo por Equipamento'!$H$4:$H$3000,'Resumo por Equipamento'!$B$4:$B$3000,$A11,'Resumo por Equipamento'!$A$4:$A$3000,">="&Diretoria!$B$4,'Resumo por Equipamento'!$A$4:$A$3000,"<="&Diretoria!$D$4)) | J11: =IF(Equipamentos!$A11="","",IFERROR(IF(OR(D11=0,I11=0),"—",I11/D11),"—")) | K11: =IF(Equipamentos!$A11="","",SUMIFS('Resumo por Equipamento'!$J$4:$J$3000,'Resumo por Equipamento'!$B$4:$B$3000,$A11,'Resumo por Equipamento'!$A$4:$A$3000,">="&Diretoria!$B$4,'Resumo por Equipamento'!$A$4:$A$3000,"<="&Diretoria!$D$4))
A12: =IF(Equipamentos!$A12="","",Equipamentos!$A12) | B12: =IF(Equipamentos!$A12="","",Equipamentos!$B12) | C12: =IF(Equipamentos!$A12="","",COUNTIFS('Resumo por Equipamento'!$B$4:$B$3000,$A12,'Resumo por Equipamento'!$A$4:$A$3000,">="&Diretoria!$B$4,'Resumo por Equipamento'!$A$4:$A$3000,"<="&Diretoria!$D$4,'Resumo por Equipamento'!$C$4:$C$3000,">0")) | D12: =IF(Equipamentos!$A12="","",SUMIFS('Resumo por Equipamento'!$C$4:$C$3000,'Resumo por Equipamento'!$B$4:$B$3000,$A12,'Resumo por Equipamento'!$A$4:$A$3000,">="&Diretoria!$B$4,'Resumo por Equipamento'!$A$4:$A$3000,"<="&Diretoria!$D$4)) | E12: =IF(Equipamentos!$A12="","",SUMIFS('Resumo por Equipamento'!$D$4:$D$3000,'Resumo por Equipamento'!$B$4:$B$3000,$A12,'Resumo por Equipamento'!$A$4:$A$3000,">="&Diretoria!$B$4,'Resumo por Equipamento'!$A$4:$A$3000,"<="&Diretoria!$D$4)) | F12: =IF(Equipamentos!$A12="","",IFERROR(IF(E12=0,"—",D12/E12),"—")) | G12: =IF(Equipamentos!$A12="","",SUMIFS('Resumo por Equipamento'!$F$4:$F$3000,'Resumo por Equipamento'!$B$4:$B$3000,$A12,'Resumo por Equipamento'!$A$4:$A$3000,">="&Diretoria!$B$4,'Resumo por Equipamento'!$A$4:$A$3000,"<="&Diretoria!$D$4)) | H12: =IF(Equipamentos!$A12="","",IFERROR(IF(G12=0,"—",D12/G12),"—")) | I12: =IF(Equipamentos!$A12="","",SUMIFS('Resumo por Equipamento'!$H$4:$H$3000,'Resumo por Equipamento'!$B$4:$B$3000,$A12,'Resumo por Equipamento'!$A$4:$A$3000,">="&Diretoria!$B$4,'Resumo por Equipamento'!$A$4:$A$3000,"<="&Diretoria!$D$4)) | J12: =IF(Equipamentos!$A12="","",IFERROR(IF(OR(D12=0,I12=0),"—",I12/D12),"—")) | K12: =IF(Equipamentos!$A12="","",SUMIFS('Resumo por Equipamento'!$J$4:$J$3000,'Resumo por Equipamento'!$B$4:$B$3000,$A12,'Resumo por Equipamento'!$A$4:$A$3000,">="&Diretoria!$B$4,'Resumo por Equipamento'!$A$4:$A$3000,"<="&Diretoria!$D$4))
A13: =IF(Equipamentos!$A13="","",Equipamentos!$A13) | B13: =IF(Equipamentos!$A13="","",Equipamentos!$B13) | C13: =IF(Equipamentos!$A13="","",COUNTIFS('Resumo por Equipamento'!$B$4:$B$3000,$A13,'Resumo por Equipamento'!$A$4:$A$3000,">="&Diretoria!$B$4,'Resumo por Equipamento'!$A$4:$A$3000,"<="&Diretoria!$D$4,'Resumo por Equipamento'!$C$4:$C$3000,">0")) | D13: =IF(Equipamentos!$A13="","",SUMIFS('Resumo por Equipamento'!$C$4:$C$3000,'Resumo por Equipamento'!$B$4:$B$3000,$A13,'Resumo por Equipamento'!$A$4:$A$3000,">="&Diretoria!$B$4,'Resumo por Equipamento'!$A$4:$A$3000,"<="&Diretoria!$D$4)) | E13: =IF(Equipamentos!$A13="","",SUMIFS('Resumo por Equipamento'!$D$4:$D$3000,'Resumo por Equipamento'!$B$4:$B$3000,$A13,'Resumo por Equipamento'!$A$4:$A$3000,">="&Diretoria!$B$4,'Resumo por Equipamento'!$A$4:$A$3000,"<="&Diretoria!$D$4)) | F13: =IF(Equipamentos!$A13="","",IFERROR(IF(E13=0,"—",D13/E13),"—")) | G13: =IF(Equipamentos!$A13="","",SUMIFS('Resumo por Equipamento'!$F$4:$F$3000,'Resumo por Equipamento'!$B$4:$B$3000,$A13,'Resumo por Equipamento'!$A$4:$A$3000,">="&Diretoria!$B$4,'Resumo por Equipamento'!$A$4:$A$3000,"<="&Diretoria!$D$4)) | H13: =IF(Equipamentos!$A13="","",IFERROR(IF(G13=0,"—",D13/G13),"—")) | I13: =IF(Equipamentos!$A13="","",SUMIFS('Resumo por Equipamento'!$H$4:$H$3000,'Resumo por Equipamento'!$B$4:$B$3000,$A13,'Resumo por Equipamento'!$A$4:$A$3000,">="&Diretoria!$B$4,'Resumo por Equipamento'!$A$4:$A$3000,"<="&Diretoria!$D$4)) | J13: =IF(Equipamentos!$A13="","",IFERROR(IF(OR(D13=0,I13=0),"—",I13/D13),"—")) | K13: =IF(Equipamentos!$A13="","",SUMIFS('Resumo por Equipamento'!$J$4:$J$3000,'Resumo por Equipamento'!$B$4:$B$3000,$A13,'Resumo por Equipamento'!$A$4:$A$3000,">="&Diretoria!$B$4,'Resumo por Equipamento'!$A$4:$A$3000,"<="&Diretoria!$D$4))
A14: =IF(Equipamentos!$A14="","",Equipamentos!$A14) | B14: =IF(Equipamentos!$A14="","",Equipamentos!$B14) | C14: =IF(Equipamentos!$A14="","",COUNTIFS('Resumo por Equipamento'!$B$4:$B$3000,$A14,'Resumo por Equipamento'!$A$4:$A$3000,">="&Diretoria!$B$4,'Resumo por Equipamento'!$A$4:$A$3000,"<="&Diretoria!$D$4,'Resumo por Equipamento'!$C$4:$C$3000,">0")) | D14: =IF(Equipamentos!$A14="","",SUMIFS('Resumo por Equipamento'!$C$4:$C$3000,'Resumo por Equipamento'!$B$4:$B$3000,$A14,'Resumo por Equipamento'!$A$4:$A$3000,">="&Diretoria!$B$4,'Resumo por Equipamento'!$A$4:$A$3000,"<="&Diretoria!$D$4)) | E14: =IF(Equipamentos!$A14="","",SUMIFS('Resumo por Equipamento'!$D$4:$D$3000,'Resumo por Equipamento'!$B$4:$B$3000,$A14,'Resumo por Equipamento'!$A$4:$A$3000,">="&Diretoria!$B$4,'Resumo por Equipamento'!$A$4:$A$3000,"<="&Diretoria!$D$4)) | F14: =IF(Equipamentos!$A14="","",IFERROR(IF(E14=0,"—",D14/E14),"—")) | G14: =IF(Equipamentos!$A14="","",SUMIFS('Resumo por Equipamento'!$F$4:$F$3000,'Resumo por Equipamento'!$B$4:$B$3000,$A14,'Resumo por Equipamento'!$A$4:$A$3000,">="&Diretoria!$B$4,'Resumo por Equipamento'!$A$4:$A$3000,"<="&Diretoria!$D$4)) | H14: =IF(Equipamentos!$A14="","",IFERROR(IF(G14=0,"—",D14/G14),"—")) | I14: =IF(Equipamentos!$A14="","",SUMIFS('Resumo por Equipamento'!$H$4:$H$3000,'Resumo por Equipamento'!$B$4:$B$3000,$A14,'Resumo por Equipamento'!$A$4:$A$3000,">="&Diretoria!$B$4,'Resumo por Equipamento'!$A$4:$A$3000,"<="&Diretoria!$D$4)) | J14: =IF(Equipamentos!$A14="","",IFERROR(IF(OR(D14=0,I14=0),"—",I14/D14),"—")) | K14: =IF(Equipamentos!$A14="","",SUMIFS('Resumo por Equipamento'!$J$4:$J$3000,'Resumo por Equipamento'!$B$4:$B$3000,$A14,'Resumo por Equipamento'!$A$4:$A$3000,">="&Diretoria!$B$4,'Resumo por Equipamento'!$A$4:$A$3000,"<="&Diretoria!$D$4))
A15: =IF(Equipamentos!$A15="","",Equipamentos!$A15) | B15: =IF(Equipamentos!$A15="","",Equipamentos!$B15) | C15: =IF(Equipamentos!$A15="","",COUNTIFS('Resumo por Equipamento'!$B$4:$B$3000,$A15,'Resumo por Equipamento'!$A$4:$A$3000,">="&Diretoria!$B$4,'Resumo por Equipamento'!$A$4:$A$3000,"<="&Diretoria!$D$4,'Resumo por Equipamento'!$C$4:$C$3000,">0")) | D15: =IF(Equipamentos!$A15="","",SUMIFS('Resumo por Equipamento'!$C$4:$C$3000,'Resumo por Equipamento'!$B$4:$B$3000,$A15,'Resumo por Equipamento'!$A$4:$A$3000,">="&Diretoria!$B$4,'Resumo por Equipamento'!$A$4:$A$3000,"<="&Diretoria!$D$4)) | E15: =IF(Equipamentos!$A15="","",SUMIFS('Resumo por Equipamento'!$D$4:$D$3000,'Resumo por Equipamento'!$B$4:$B$3000,$A15,'Resumo por Equipamento'!$A$4:$A$3000,">="&Diretoria!$B$4,'Resumo por Equipamento'!$A$4:$A$3000,"<="&Diretoria!$D$4)) | F15: =IF(Equipamentos!$A15="","",IFERROR(IF(E15=0,"—",D15/E15),"—")) | G15: =IF(Equipamentos!$A15="","",SUMIFS('Resumo por Equipamento'!$F$4:$F$3000,'Resumo por Equipamento'!$B$4:$B$3000,$A15,'Resumo por Equipamento'!$A$4:$A$3000,">="&Diretoria!$B$4,'Resumo por Equipamento'!$A$4:$A$3000,"<="&Diretoria!$D$4)) | H15: =IF(Equipamentos!$A15="","",IFERROR(IF(G15=0,"—",D15/G15),"—")) | I15: =IF(Equipamentos!$A15="","",SUMIFS('Resumo por Equipamento'!$H$4:$H$3000,'Resumo por Equipamento'!$B$4:$B$3000,$A15,'Resumo por Equipamento'!$A$4:$A$3000,">="&Diretoria!$B$4,'Resumo por Equipamento'!$A$4:$A$3000,"<="&Diretoria!$D$4)) | J15: =IF(Equipamentos!$A15="","",IFERROR(IF(OR(D15=0,I15=0),"—",I15/D15),"—")) | K15: =IF(Equipamentos!$A15="","",SUMIFS('Resumo por Equipamento'!$J$4:$J$3000,'Resumo por Equipamento'!$B$4:$B$3000,$A15,'Resumo por Equipamento'!$A$4:$A$3000,">="&Diretoria!$B$4,'Resumo por Equipamento'!$A$4:$A$3000,"<="&Diretoria!$D$4))
... A33: =IF(Equipamentos!$A33="","",Equipamentos!$A33) | B33: =IF(Equipamentos!$A33="","",Equipamentos!$B33) | C33: =IF(Equipamentos!$A33="","",COUNTIFS('Resumo por Equipamento'!$B$4:$B$3000,$A33,'Resumo por Equipamento'!$A$4:$A$3000,">="&Diretoria!$B$4,'Resumo por Equipamento'!$A$4:$A$3000,"<="&Diretoria!$D$4,'Resumo por Equipamento'!$C$4:$C$3000,">0")) | D33: =IF(Equipamentos!$A33="","",SUMIFS('Resumo por Equipamento'!$C$4:$C$3000,'Resumo por Equipamento'!$B$4:$B$3000,$A33,'Resumo por Equipamento'!$A$4:$A$3000,">="&Diretoria!$B$4,'Resumo por Equipamento'!$A$4:$A$3000,"<="&Diretoria!$D$4)) | E33: =IF(Equipamentos!$A33="","",SUMIFS('Resumo por Equipamento'!$D$4:$D$3000,'Resumo por Equipamento'!$B$4:$B$3000,$A33,'Resumo por Equipamento'!$A$4:$A$3000,">="&Diretoria!$B$4,'Resumo por Equipamento'!$A$4:$A$3000,"<="&Diretoria!$D$4)) | F33: =IF(Equipamentos!$A33="","",IFERROR(IF(E33=0,"—",D33/E33),"—")) | G33: =IF(Equipamentos!$A33="","",SUMIFS('Resumo por Equipamento'!$F$4:$F$3000,'Resumo por Equipamento'!$B$4:$B$3000,$A33,'Resumo por Equipamento'!$A$4:$A$3000,">="&Diretoria!$B$4,'Resumo por Equipamento'!$A$4:$A$3000,"<="&Diretoria!$D$4)) | H33: =IF(Equipamentos!$A33="","",IFERROR(IF(G33=0,"—",D33/G33),"—")) | I33: =IF(Equipamentos!$A33="","",SUMIFS('Resumo por Equipamento'!$H$4:$H$3000,'Resumo por Equipamento'!$B$4:$B$3000,$A33,'Resumo por Equipamento'!$A$4:$A$3000,">="&Diretoria!$B$4,'Resumo por Equipamento'!$A$4:$A$3000,"<="&Diretoria!$D$4)) | J33: =IF(Equipamentos!$A33="","",IFERROR(IF(OR(D33=0,I33=0),"—",I33/D33),"—")) | K33: =IF(Equipamentos!$A33="","",SUMIFS('Resumo por Equipamento'!$J$4:$J$3000,'Resumo por Equipamento'!$B$4:$B$3000,$A33,'Resumo por Equipamento'!$A$4:$A$3000,">="&Diretoria!$B$4,'Resumo por Equipamento'!$A$4:$A$3000,"<="&Diretoria!$D$4))
A35: TOTAL DA FROTA | C35: =SUM(C4:C33) | D35: =SUM(D4:D33) | E35: =SUM(E4:E33) | F35: =IFERROR(D35/E35,"—") | G35: =SUM(G4:G33) | H35: =IFERROR(D35/G35,"—") | I35: =SUM(I4:I33) | J35: =IFERROR(I35/D35,"—") | K35: =SUM(K4:K33)

Sheet Por Operador
A1: DESEMPENHO POR OPERADOR
A2: Período definido na aba Diretoria. Fonte: aba Resumo por Operador (preenchida pelo app).
A3: Operador | B3: Dias trabalhados | C3: Consumo (L) | D3: Horas | E3: L/h | F3: Produção (t) | G3: L/Ton | H3: Viagens
A4: =IF(Operadores!$A4="","",Operadores!$A4) | B4: =IF(Operadores!$A4="","",COUNTIFS('Resumo por Operador'!$B$4:$B$3000,$A4,'Resumo por Operador'!$A$4:$A$3000,">="&Diretoria!$B$4,'Resumo por Operador'!$A$4:$A$3000,"<="&Diretoria!$D$4)) | C4: =IF(Operadores!$A4="","",SUMIFS('Resumo por Operador'!$D$4:$D$3000,'Resumo por Operador'!$B$4:$B$3000,$A4,'Resumo por Operador'!$A$4:$A$3000,">="&Diretoria!$B$4,'Resumo por Operador'!$A$4:$A$3000,"<="&Diretoria!$D$4)) | D4: =IF(Operadores!$A4="","",SUMIFS('Resumo por Operador'!$E$4:$E$3000,'Resumo por Operador'!$B$4:$B$3000,$A4,'Resumo por Operador'!$A$4:$A$3000,">="&Diretoria!$B$4,'Resumo por Operador'!$A$4:$A$3000,"<="&Diretoria!$D$4)) | E4: =IF(Operadores!$A4="","",IFERROR(IF(D4=0,"—",C4/D4),"—")) | F4: =IF(Operadores!$A4="","",SUMIFS('Resumo por Operador'!$G$4:$G$3000,'Resumo por Operador'!$B$4:$B$3000,$A4,'Resumo por Operador'!$A$4:$A$3000,">="&Diretoria!$B$4,'Resumo por Operador'!$A$4:$A$3000,"<="&Diretoria!$D$4)) | G4: =IF(Operadores!$A4="","",IFERROR(IF(F4=0,"—",C4/F4),"—")) | H4: =IF(Operadores!$A4="","",SUMIFS('Resumo por Operador'!$I$4:$I$3000,'Resumo por Operador'!$B$4:$B$3000,$A4,'Resumo por Operador'!$A$4:$A$3000,">="&Diretoria!$B$4,'Resumo por Operador'!$A$4:$A$3000,"<="&Diretoria!$D$4))
A5: =IF(Operadores!$A5="","",Operadores!$A5) | B5: =IF(Operadores!$A5="","",COUNTIFS('Resumo por Operador'!$B$4:$B$3000,$A5,'Resumo por Operador'!$A$4:$A$3000,">="&Diretoria!$B$4,'Resumo por Operador'!$A$4:$A$3000,"<="&Diretoria!$D$4)) | C5: =IF(Operadores!$A5="","",SUMIFS('Resumo por Operador'!$D$4:$D$3000,'Resumo por Operador'!$B$4:$B$3000,$A5,'Resumo por Operador'!$A$4:$A$3000,">="&Diretoria!$B$4,'Resumo por Operador'!$A$4:$A$3000,"<="&Diretoria!$D$4)) | D5: =IF(Operadores!$A5="","",SUMIFS('Resumo por Operador'!$E$4:$E$3000,'Resumo por Operador'!$B$4:$B$3000,$A5,'Resumo por Operador'!$A$4:$A$3000,">="&Diretoria!$B$4,'Resumo por Operador'!$A$4:$A$3000,"<="&Diretoria!$D$4)) | E5: =IF(Operadores!$A5="","",IFERROR(IF(D5=0,"—",C5/D5),"—")) | F5: =IF(Operadores!$A5="","",SUMIFS('Resumo por Operador'!$G$4:$G$3000,'Resumo por Operador'!$B$4:$B$3000,$A5,'Resumo por Operador'!$A$4:$A$3000,">="&Diretoria!$B$4,'Resumo por Operador'!$A$4:$A$3000,"<="&Diretoria!$D$4)) | G5: =IF(Operadores!$A5="","",IFERROR(IF(F5=0,"—",C5/F5),"—")) | H5: =IF(Operadores!$A5="","",SUMIFS('Resumo por Operador'!$I$4:$I$3000,'Resumo por Operador'!$B$4:$B$3000,$A5,'Resumo por Operador'!$A$4:$A$3000,">="&Diretoria!$B$4,'Resumo por Operador'!$A$4:$A$3000,"<="&Diretoria!$D$4))
A6: =IF(Operadores!$A6="","",Operadores!$A6) | B6: =IF(Operadores!$A6="","",COUNTIFS('Resumo por Operador'!$B$4:$B$3000,$A6,'Resumo por Operador'!$A$4:$A$3000,">="&Diretoria!$B$4,'Resumo por Operador'!$A$4:$A$3000,"<="&Diretoria!$D$4)) | C6: =IF(Operadores!$A6="","",SUMIFS('Resumo por Operador'!$D$4:$D$3000,'Resumo por Operador'!$B$4:$B$3000,$A6,'Resumo por Operador'!$A$4:$A$3000,">="&Diretoria!$B$4,'Resumo por Operador'!$A$4:$A$3000,"<="&Diretoria!$D$4)) | D6: =IF(Operadores!$A6="","",SUMIFS('Resumo por Operador'!$E$4:$E$3000,'Resumo por Operador'!$B$4:$B$3000,$A6,'Resumo por Operador'!$A$4:$A$3000,">="&Diretoria!$B$4,'Resumo por Operador'!$A$4:$A$3000,"<="&Diretoria!$D$4)) | E6: =IF(Operadores!$A6="","",IFERROR(IF(D6=0,"—",C6/D6),"—")) | F6: =IF(Operadores!$A6="","",SUMIFS('Resumo por Operador'!$G$4:$G$3000,'Resumo por Operador'!$B$4:$B$3000,$A6,'Resumo por Operador'!$A$4:$A$3000,">="&Diretoria!$B$4,'Resumo por Operador'!$A$4:$A$3000,"<="&Diretoria!$D$4)) | G6: =IF(Operadores!$A6="","",IFERROR(IF(F6=0,"—",C6/F6),"—")) | H6: =IF(Operadores!$A6="","",SUMIFS('Resumo por Operador'!$I$4:$I$3000,'Resumo por Operador'!$B$4:$B$3000,$A6,'Resumo por Operador'!$A$4:$A$3000,">="&Diretoria!$B$4,'Resumo por Operador'!$A$4:$A$3000,"<="&Diretoria!$D$4))
A7: =IF(Operadores!$A7="","",Operadores!$A7) | B7: =IF(Operadores!$A7="","",COUNTIFS('Resumo por Operador'!$B$4:$B$3000,$A7,'Resumo por Operador'!$A$4:$A$3000,">="&Diretoria!$B$4,'Resumo por Operador'!$A$4:$A$3000,"<="&Diretoria!$D$4)) | C7: =IF(Operadores!$A7="","",SUMIFS('Resumo por Operador'!$D$4:$D$3000,'Resumo por Operador'!$B$4:$B$3000,$A7,'Resumo por Operador'!$A$4:$A$3000,">="&Diretoria!$B$4,'Resumo por Operador'!$A$4:$A$3000,"<="&Diretoria!$D$4)) | D7: =IF(Operadores!$A7="","",SUMIFS('Resumo por Operador'!$E$4:$E$3000,'Resumo por Operador'!$B$4:$B$3000,$A7,'Resumo por Operador'!$A$4:$A$3000,">="&Diretoria!$B$4,'Resumo por Operador'!$A$4:$A$3000,"<="&Diretoria!$D$4)) | E7: =IF(Operadores!$A7="","",IFERROR(IF(D7=0,"—",C7/D7),"—")) | F7: =IF(Operadores!$A7="","",SUMIFS('Resumo por Operador'!$G$4:$G$3000,'Resumo por Operador'!$B$4:$B$3000,$A7,'Resumo por Operador'!$A$4:$A$3000,">="&Diretoria!$B$4,'Resumo por Operador'!$A$4:$A$3000,"<="&Diretoria!$D$4)) | G7: =IF(Operadores!$A7="","",IFERROR(IF(F7=0,"—",C7/F7),"—")) | H7: =IF(Operadores!$A7="","",SUMIFS('Resumo por Operador'!$I$4:$I$3000,'Resumo por Operador'!$B$4:$B$3000,$A7,'Resumo por Operador'!$A$4:$A$3000,">="&Diretoria!$B$4,'Resumo por Operador'!$A$4:$A$3000,"<="&Diretoria!$D$4))
A8: =IF(Operadores!$A8="","",Operadores!$A8) | B8: =IF(Operadores!$A8="","",COUNTIFS('Resumo por Operador'!$B$4:$B$3000,$A8,'Resumo por Operador'!$A$4:$A$3000,">="&Diretoria!$B$4,'Resumo por Operador'!$A$4:$A$3000,"<="&Diretoria!$D$4)) | C8: =IF(Operadores!$A8="","",SUMIFS('Resumo por Operador'!$D$4:$D$3000,'Resumo por Operador'!$B$4:$B$3000,$A8,'Resumo por Operador'!$A$4:$A$3000,">="&Diretoria!$B$4,'Resumo por Operador'!$A$4:$A$3000,"<="&Diretoria!$D$4)) | D8: =IF(Operadores!$A8="","",SUMIFS('Resumo por Operador'!$E$4:$E$3000,'Resumo por Operador'!$B$4:$B$3000,$A8,'Resumo por Operador'!$A$4:$A$3000,">="&Diretoria!$B$4,'Resumo por Operador'!$A$4:$A$3000,"<="&Diretoria!$D$4)) | E8: =IF(Operadores!$A8="","",IFERROR(IF(D8=0,"—",C8/D8),"—")) | F8: =IF(Operadores!$A8="","",SUMIFS('Resumo por Operador'!$G$4:$G$3000,'Resumo por Operador'!$B$4:$B$3000,$A8,'Resumo por Operador'!$A$4:$A$3000,">="&Diretoria!$B$4,'Resumo por Operador'!$A$4:$A$3000,"<="&Diretoria!$D$4)) | G8: =IF(Operadores!$A8="","",IFERROR(IF(F8=0,"—",C8/F8),"—")) | H8: =IF(Operadores!$A8="","",SUMIFS('Resumo por Operador'!$I$4:$I$3000,'Resumo por Operador'!$B$4:$B$3000,$A8,'Resumo por Operador'!$A$4:$A$3000,">="&Diretoria!$B$4,'Resumo por Operador'!$A$4:$A$3000,"<="&Diretoria!$D$4))
A9: =IF(Operadores!$A9="","",Operadores!$A9) | B9: =IF(Operadores!$A9="","",COUNTIFS('Resumo por Operador'!$B$4:$B$3000,$A9,'Resumo por Operador'!$A$4:$A$3000,">="&Diretoria!$B$4,'Resumo por Operador'!$A$4:$A$3000,"<="&Diretoria!$D$4)) | C9: =IF(Operadores!$A9="","",SUMIFS('Resumo por Operador'!$D$4:$D$3000,'Resumo por Operador'!$B$4:$B$3000,$A9,'Resumo por Operador'!$A$4:$A$3000,">="&Diretoria!$B$4,'Resumo por Operador'!$A$4:$A$3000,"<="&Diretoria!$D$4)) | D9: =IF(Operadores!$A9="","",SUMIFS('Resumo por Operador'!$E$4:$E$3000,'Resumo por Operador'!$B$4:$B$3000,$A9,'Resumo por Operador'!$A$4:$A$3000,">="&Diretoria!$B$4,'Resumo por Operador'!$A$4:$A$3000,"<="&Diretoria!$D$4)) | E9: =IF(Operadores!$A9="","",IFERROR(IF(D9=0,"—",C9/D9),"—")) | F9: =IF(Operadores!$A9="","",SUMIFS('Resumo por Operador'!$G$4:$G$3000,'Resumo por Operador'!$B$4:$B$3000,$A9,'Resumo por Operador'!$A$4:$A$3000,">="&Diretoria!$B$4,'Resumo por Operador'!$A$4:$A$3000,"<="&Diretoria!$D$4)) | G9: =IF(Operadores!$A9="","",IFERROR(IF(F9=0,"—",C9/F9),"—")) | H9: =IF(Operadores!$A9="","",SUMIFS('Resumo por Operador'!$I$4:$I$3000,'Resumo por Operador'!$B$4:$B$3000,$A9,'Resumo por Operador'!$A$4:$A$3000,">="&Diretoria!$B$4,'Resumo por Operador'!$A$4:$A$3000,"<="&Diretoria!$D$4))
A10: =IF(Operadores!$A10="","",Operadores!$A10) | B10: =IF(Operadores!$A10="","",COUNTIFS('Resumo por Operador'!$B$4:$B$3000,$A10,'Resumo por Operador'!$A$4:$A$3000,">="&Diretoria!$B$4,'Resumo por Operador'!$A$4:$A$3000,"<="&Diretoria!$D$4)) | C10: =IF(Operadores!$A10="","",SUMIFS('Resumo por Operador'!$D$4:$D$3000,'Resumo por Operador'!$B$4:$B$3000,$A10,'Resumo por Operador'!$A$4:$A$3000,">="&Diretoria!$B$4,'Resumo por Operador'!$A$4:$A$3000,"<="&Diretoria!$D$4)) | D10: =IF(Operadores!$A10="","",SUMIFS('Resumo por Operador'!$E$4:$E$3000,'Resumo por Operador'!$B$4:$B$3000,$A10,'Resumo por Operador'!$A$4:$A$3000,">="&Diretoria!$B$4,'Resumo por Operador'!$A$4:$A$3000,"<="&Diretoria!$D$4)) | E10: =IF(Operadores!$A10="","",IFERROR(IF(D10=0,"—",C10/D10),"—")) | F10: =IF(Operadores!$A10="","",SUMIFS('Resumo por Operador'!$G$4:$G$3000,'Resumo por Operador'!$B$4:$B$3000,$A10,'Resumo por Operador'!$A$4:$A$3000,">="&Diretoria!$B$4,'Resumo por Operador'!$A$4:$A$3000,"<="&Diretoria!$D$4)) | G10: =IF(Operadores!$A10="","",IFERROR(IF(F10=0,"—",C10/F10),"—")) | H10: =IF(Operadores!$A10="","",SUMIFS('Resumo por Operador'!$I$4:$I$3000,'Resumo por Operador'!$B$4:$B$3000,$A10,'Resumo por Operador'!$A$4:$A$3000,">="&Diretoria!$B$4,'Resumo por Operador'!$A$4:$A$3000,"<="&Diretoria!$D$4))
A11: =IF(Operadores!$A11="","",Operadores!$A11) | B11: =IF(Operadores!$A11="","",COUNTIFS('Resumo por Operador'!$B$4:$B$3000,$A11,'Resumo por Operador'!$A$4:$A$3000,">="&Diretoria!$B$4,'Resumo por Operador'!$A$4:$A$3000,"<="&Diretoria!$D$4)) | C11: =IF(Operadores!$A11="","",SUMIFS('Resumo por Operador'!$D$4:$D$3000,'Resumo por Operador'!$B$4:$B$3000,$A11,'Resumo por Operador'!$A$4:$A$3000,">="&Diretoria!$B$4,'Resumo por Operador'!$A$4:$A$3000,"<="&Diretoria!$D$4)) | D11: =IF(Operadores!$A11="","",SUMIFS('Resumo por Operador'!$E$4:$E$3000,'Resumo por Operador'!$B$4:$B$3000,$A11,'Resumo por Operador'!$A$4:$A$3000,">="&Diretoria!$B$4,'Resumo por Operador'!$A$4:$A$3000,"<="&Diretoria!$D$4)) | E11: =IF(Operadores!$A11="","",IFERROR(IF(D11=0,"—",C11/D11),"—")) | F11: =IF(Operadores!$A11="","",SUMIFS('Resumo por Operador'!$G$4:$G$3000,'Resumo por Operador'!$B$4:$B$3000,$A11,'Resumo por Operador'!$A$4:$A$3000,">="&Diretoria!$B$4,'Resumo por Operador'!$A$4:$A$3000,"<="&Diretoria!$D$4)) | G11: =IF(Operadores!$A11="","",IFERROR(IF(F11=0,"—",C11/F11),"—")) | H11: =IF(Operadores!$A11="","",SUMIFS('Resumo por Operador'!$I$4:$I$3000,'Resumo por Operador'!$B$4:$B$3000,$A11,'Resumo por Operador'!$A$4:$A$3000,">="&Diretoria!$B$4,'Resumo por Operador'!$A$4:$A$3000,"<="&Diretoria!$D$4))
A12: =IF(Operadores!$A12="","",Operadores!$A12) | B12: =IF(Operadores!$A12="","",COUNTIFS('Resumo por Operador'!$B$4:$B$3000,$A12,'Resumo por Operador'!$A$4:$A$3000,">="&Diretoria!$B$4,'Resumo por Operador'!$A$4:$A$3000,"<="&Diretoria!$D$4)) | C12: =IF(Operadores!$A12="","",SUMIFS('Resumo por Operador'!$D$4:$D$3000,'Resumo por Operador'!$B$4:$B$3000,$A12,'Resumo por Operador'!$A$4:$A$3000,">="&Diretoria!$B$4,'Resumo por Operador'!$A$4:$A$3000,"<="&Diretoria!$D$4)) | D12: =IF(Operadores!$A12="","",SUMIFS('Resumo por Operador'!$E$4:$E$3000,'Resumo por Operador'!$B$4:$B$3000,$A12,'Resumo por Operador'!$A$4:$A$3000,">="&Diretoria!$B$4,'Resumo por Operador'!$A$4:$A$3000,"<="&Diretoria!$D$4)) | E12: =IF(Operadores!$A12="","",IFERROR(IF(D12=0,"—",C12/D12),"—")) | F12: =IF(Operadores!$A12="","",SUMIFS('Resumo por Operador'!$G$4:$G$3000,'Resumo por Operador'!$B$4:$B$3000,$A12,'Resumo por Operador'!$A$4:$A$3000,">="&Diretoria!$B$4,'Resumo por Operador'!$A$4:$A$3000,"<="&Diretoria!$D$4)) | G12: =IF(Operadores!$A12="","",IFERROR(IF(F12=0,"—",C12/F12),"—")) | H12: =IF(Operadores!$A12="","",SUMIFS('Resumo por Operador'!$I$4:$I$3000,'Resumo por Operador'!$B$4:$B$3000,$A12,'Resumo por Operador'!$A$4:$A$3000,">="&Diretoria!$B$4,'Resumo por Operador'!$A$4:$A$3000,"<="&Diretoria!$D$4))
A13: =IF(Operadores!$A13="","",Operadores!$A13) | B13: =IF(Operadores!$A13="","",COUNTIFS('Resumo por Operador'!$B$4:$B$3000,$A13,'Resumo por Operador'!$A$4:$A$3000,">="&Diretoria!$B$4,'Resumo por Operador'!$A$4:$A$3000,"<="&Diretoria!$D$4)) | C13: =IF(Operadores!$A13="","",SUMIFS('Resumo por Operador'!$D$4:$D$3000,'Resumo por Operador'!$B$4:$B$3000,$A13,'Resumo por Operador'!$A$4:$A$3000,">="&Diretoria!$B$4,'Resumo por Operador'!$A$4:$A$3000,"<="&Diretoria!$D$4)) | D13: =IF(Operadores!$A13="","",SUMIFS('Resumo por Operador'!$E$4:$E$3000,'Resumo por Operador'!$B$4:$B$3000,$A13,'Resumo por Operador'!$A$4:$A$3000,">="&Diretoria!$B$4,'Resumo por Operador'!$A$4:$A$3000,"<="&Diretoria!$D$4)) | E13: =IF(Operadores!$A13="","",IFERROR(IF(D13=0,"—",C13/D13),"—")) | F13: =IF(Operadores!$A13="","",SUMIFS('Resumo por Operador'!$G$4:$G$3000,'Resumo por Operador'!$B$4:$B$3000,$A13,'Resumo por Operador'!$A$4:$A$3000,">="&Diretoria!$B$4,'Resumo por Operador'!$A$4:$A$3000,"<="&Diretoria!$D$4)) | G13: =IF(Operadores!$A13="","",IFERROR(IF(F13=0,"—",C13/F13),"—")) | H13: =IF(Operadores!$A13="","",SUMIFS('Resumo por Operador'!$I$4:$I$3000,'Resumo por Operador'!$B$4:$B$3000,$A13,'Resumo por Operador'!$A$4:$A$3000,">="&Diretoria!$B$4,'Resumo por Operador'!$A$4:$A$3000,"<="&Diretoria!$D$4))
A14: =IF(Operadores!$A14="","",Operadores!$A14) | B14: =IF(Operadores!$A14="","",COUNTIFS('Resumo por Operador'!$B$4:$B$3000,$A14,'Resumo por Operador'!$A$4:$A$3000,">="&Diretoria!$B$4,'Resumo por Operador'!$A$4:$A$3000,"<="&Diretoria!$D$4)) | C14: =IF(Operadores!$A14="","",SUMIFS('Resumo por Operador'!$D$4:$D$3000,'Resumo por Operador'!$B$4:$B$3000,$A14,'Resumo por Operador'!$A$4:$A$3000,">="&Diretoria!$B$4,'Resumo por Operador'!$A$4:$A$3000,"<="&Diretoria!$D$4)) | D14: =IF(Operadores!$A14="","",SUMIFS('Resumo por Operador'!$E$4:$E$3000,'Resumo por Operador'!$B$4:$B$3000,$A14,'Resumo por Operador'!$A$4:$A$3000,">="&Diretoria!$B$4,'Resumo por Operador'!$A$4:$A$3000,"<="&Diretoria!$D$4)) | E14: =IF(Operadores!$A14="","",IFERROR(IF(D14=0,"—",C14/D14),"—")) | F14: =IF(Operadores!$A14="","",SUMIFS('Resumo por Operador'!$G$4:$G$3000,'Resumo por Operador'!$B$4:$B$3000,$A14,'Resumo por Operador'!$A$4:$A$3000,">="&Diretoria!$B$4,'Resumo por Operador'!$A$4:$A$3000,"<="&Diretoria!$D$4)) | G14: =IF(Operadores!$A14="","",IFERROR(IF(F14=0,"—",C14/F14),"—")) | H14: =IF(Operadores!$A14="","",SUMIFS('Resumo por Operador'!$I$4:$I$3000,'Resumo por Operador'!$B$4:$B$3000,$A14,'Resumo por Operador'!$A$4:$A$3000,">="&Diretoria!$B$4,'Resumo por Operador'!$A$4:$A$3000,"<="&Diretoria!$D$4))
A15: =IF(Operadores!$A15="","",Operadores!$A15) | B15: =IF(Operadores!$A15="","",COUNTIFS('Resumo por Operador'!$B$4:$B$3000,$A15,'Resumo por Operador'!$A$4:$A$3000,">="&Diretoria!$B$4,'Resumo por Operador'!$A$4:$A$3000,"<="&Diretoria!$D$4)) | C15: =IF(Operadores!$A15="","",SUMIFS('Resumo por Operador'!$D$4:$D$3000,'Resumo por Operador'!$B$4:$B$3000,$A15,'Resumo por Operador'!$A$4:$A$3000,">="&Diretoria!$B$4,'Resumo por Operador'!$A$4:$A$3000,"<="&Diretoria!$D$4)) | D15: =IF(Operadores!$A15="","",SUMIFS('Resumo por Operador'!$E$4:$E$3000,'Resumo por Operador'!$B$4:$B$3000,$A15,'Resumo por Operador'!$A$4:$A$3000,">="&Diretoria!$B$4,'Resumo por Operador'!$A$4:$A$3000,"<="&Diretoria!$D$4)) | E15: =IF(Operadores!$A15="","",IFERROR(IF(D15=0,"—",C15/D15),"—")) | F15: =IF(Operadores!$A15="","",SUMIFS('Resumo por Operador'!$G$4:$G$3000,'Resumo por Operador'!$B$4:$B$3000,$A15,'Resumo por Operador'!$A$4:$A$3000,">="&Diretoria!$B$4,'Resumo por Operador'!$A$4:$A$3000,"<="&Diretoria!$D$4)) | G15: =IF(Operadores!$A15="","",IFERROR(IF(F15=0,"—",C15/F15),"—")) | H15: =IF(Operadores!$A15="","",SUMIFS('Resumo por Operador'!$I$4:$I$3000,'Resumo por Operador'!$B$4:$B$3000,$A15,'Resumo por Operador'!$A$4:$A$3000,">="&Diretoria!$B$4,'Resumo por Operador'!$A$4:$A$3000,"<="&Diretoria!$D$4))
... A33: =IF(Operadores!$A33="","",Operadores!$A33) | B33: =IF(Operadores!$A33="","",COUNTIFS('Resumo por Operador'!$B$4:$B$3000,$A33,'Resumo por Operador'!$A$4:$A$3000,">="&Diretoria!$B$4,'Resumo por Operador'!$A$4:$A$3000,"<="&Diretoria!$D$4)) | C33: =IF(Operadores!$A33="","",SUMIFS('Resumo por Operador'!$D$4:$D$3000,'Resumo por Operador'!$B$4:$B$3000,$A33,'Resumo por Operador'!$A$4:$A$3000,">="&Diretoria!$B$4,'Resumo por Operador'!$A$4:$A$3000,"<="&Diretoria!$D$4)) | D33: =IF(Operadores!$A33="","",SUMIFS('Resumo por Operador'!$E$4:$E$3000,'Resumo por Operador'!$B$4:$B$3000,$A33,'Resumo por Operador'!$A$4:$A$3000,">="&Diretoria!$B$4,'Resumo por Operador'!$A$4:$A$3000,"<="&Diretoria!$D$4)) | E33: =IF(Operadores!$A33="","",IFERROR(IF(D33=0,"—",C33/D33),"—")) | F33: =IF(Operadores!$A33="","",SUMIFS('Resumo por Operador'!$G$4:$G$3000,'Resumo por Operador'!$B$4:$B$3000,$A33,'Resumo por Operador'!$A$4:$A$3000,">="&Diretoria!$B$4,'Resumo por Operador'!$A$4:$A$3000,"<="&Diretoria!$D$4)) | G33: =IF(Operadores!$A33="","",IFERROR(IF(F33=0,"—",C33/F33),"—")) | H33: =IF(Operadores!$A33="","",SUMIFS('Resumo por Operador'!$I$4:$I$3000,'Resumo por Operador'!$B$4:$B$3000,$A33,'Resumo por Operador'!$A$4:$A$3000,">="&Diretoria!$B$4,'Resumo por Operador'!$A$4:$A$3000,"<="&Diretoria!$D$4))

Sheet Evolução Diária
A1: EVOLUÇÃO DIÁRIA
A2: Espelho da aba Resumo por Dia — cresce sozinha conforme o app lança.
A3: Data | B3: Consumo (L) | C3: Horas | D3: L/h | E3: Produção (t) | F3: L/Ton | G3: Viagens | H3: Equip.
A4: =IF('Resumo por Dia'!$A4="","",'Resumo por Dia'!$A4) | B4: =IF('Resumo por Dia'!$A4="","",'Resumo por Dia'!$D4) | C4: =IF('Resumo por Dia'!$A4="","",'Resumo por Dia'!$E4) | D4: =IF('Resumo por Dia'!$A4="","",'Resumo por Dia'!$F4) | E4: =IF('Resumo por Dia'!$A4="","",'Resumo por Dia'!$G4) | F4: =IF('Resumo por Dia'!$A4="","",'Resumo por Dia'!$H4) | G4: =IF('Resumo por Dia'!$A4="","",'Resumo por Dia'!$N4) | H4: =IF('Resumo por Dia'!$A4="","",'Resumo por Dia'!$B4)
A5: =IF('Resumo por Dia'!$A5="","",'Resumo por Dia'!$A5) | B5: =IF('Resumo por Dia'!$A5="","",'Resumo por Dia'!$D5) | C5: =IF('Resumo por Dia'!$A5="","",'Resumo por Dia'!$E5) | D5: =IF('Resumo por Dia'!$A5="","",'Resumo por Dia'!$F5) | E5: =IF('Resumo por Dia'!$A5="","",'Resumo por Dia'!$G5) | F5: =IF('Resumo por Dia'!$A5="","",'Resumo por Dia'!$H5) | G5: =IF('Resumo por Dia'!$A5="","",'Resumo por Dia'!$N5) | H5: =IF('Resumo por Dia'!$A5="","",'Resumo por Dia'!$B5)
A6: =IF('Resumo por Dia'!$A6="","",'Resumo por Dia'!$A6) | B6: =IF('Resumo por Dia'!$A6="","",'Resumo por Dia'!$D6) | C6: =IF('Resumo por Dia'!$A6="","",'Resumo por Dia'!$E6) | D6: =IF('Resumo por Dia'!$A6="","",'Resumo por Dia'!$F6) | E6: =IF('Resumo por Dia'!$A6="","",'Resumo por Dia'!$G6) | F6: =IF('Resumo por Dia'!$A6="","",'Resumo por Dia'!$H6) | G6: =IF('Resumo por Dia'!$A6="","",'Resumo por Dia'!$N6) | H6: =IF('Resumo por Dia'!$A6="","",'Resumo por Dia'!$B6)
A7: =IF('Resumo por Dia'!$A7="","",'Resumo por Dia'!$A7) | B7: =IF('Resumo por Dia'!$A7="","",'Resumo por Dia'!$D7) | C7: =IF('Resumo por Dia'!$A7="","",'Resumo por Dia'!$E7) | D7: =IF('Resumo por Dia'!$A7="","",'Resumo por Dia'!$F7) | E7: =IF('Resumo por Dia'!$A7="","",'Resumo por Dia'!$G7) | F7: =IF('Resumo por Dia'!$A7="","",'Resumo por Dia'!$H7) | G7: =IF('Resumo por Dia'!$A7="","",'Resumo por Dia'!$N7) | H7: =IF('Resumo por Dia'!$A7="","",'Resumo por Dia'!$B7)
A8: =IF('Resumo por Dia'!$A8="","",'Resumo por Dia'!$A8) | B8: =IF('Resumo por Dia'!$A8="","",'Resumo por Dia'!$D8) | C8: =IF('Resumo por Dia'!$A8="","",'Resumo por Dia'!$E8) | D8: =IF('Resumo por Dia'!$A8="","",'Resumo por Dia'!$F8) | E8: =IF('Resumo por Dia'!$A8="","",'Resumo por Dia'!$G8) | F8: =IF('Resumo por Dia'!$A8="","",'Resumo por Dia'!$H8) | G8: =IF('Resumo por Dia'!$A8="","",'Resumo por Dia'!$N8) | H8: =IF('Resumo por Dia'!$A8="","",'Resumo por Dia'!$B8)
A9: =IF('Resumo por Dia'!$A9="","",'Resumo por Dia'!$A9) | B9: =IF('Resumo por Dia'!$A9="","",'Resumo por Dia'!$D9) | C9: =IF('Resumo por Dia'!$A9="","",'Resumo por Dia'!$E9) | D9: =IF('Resumo por Dia'!$A9="","",'Resumo por Dia'!$F9) | E9: =IF('Resumo por Dia'!$A9="","",'Resumo por Dia'!$G9) | F9: =IF('Resumo por Dia'!$A9="","",'Resumo por Dia'!$H9) | G9: =IF('Resumo por Dia'!$A9="","",'Resumo por Dia'!$N9) | H9: =IF('Resumo por Dia'!$A9="","",'Resumo por Dia'!$B9)
A10: =IF('Resumo por Dia'!$A10="","",'Resumo por Dia'!$A10) | B10: =IF('Resumo por Dia'!$A10="","",'Resumo por Dia'!$D10) | C10: =IF('Resumo por Dia'!$A10="","",'Resumo por Dia'!$E10) | D10: =IF('Resumo por Dia'!$A10="","",'Resumo por Dia'!$F10) | E10: =IF('Resumo por Dia'!$A10="","",'Resumo por Dia'!$G10) | F10: =IF('Resumo por Dia'!$A10="","",'Resumo por Dia'!$H10) | G10: =IF('Resumo por Dia'!$A10="","",'Resumo por Dia'!$N10) | H10: =IF('Resumo por Dia'!$A10="","",'Resumo por Dia'!$B10)
A11: =IF('Resumo por Dia'!$A11="","",'Resumo por Dia'!$A11) | B11: =IF('Resumo por Dia'!$A11="","",'Resumo por Dia'!$D11) | C11: =IF('Resumo por Dia'!$A11="","",'Resumo por Dia'!$E11) | D11: =IF('Resumo por Dia'!$A11="","",'Resumo por Dia'!$F11) | E11: =IF('Resumo por Dia'!$A11="","",'Resumo por Dia'!$G11) | F11: =IF('Resumo por Dia'!$A11="","",'Resumo por Dia'!$H11) | G11: =IF('Resumo por Dia'!$A11="","",'Resumo por Dia'!$N11) | H11: =IF('Resumo por Dia'!$A11="","",'Resumo por Dia'!$B11)
A12: =IF('Resumo por Dia'!$A12="","",'Resumo por Dia'!$A12) | B12: =IF('Resumo por Dia'!$A12="","",'Resumo por Dia'!$D12) | C12: =IF('Resumo por Dia'!$A12="","",'Resumo por Dia'!$E12) | D12: =IF('Resumo por Dia'!$A12="","",'Resumo por Dia'!$F12) | E12: =IF('Resumo por Dia'!$A12="","",'Resumo por Dia'!$G12) | F12: =IF('Resumo por Dia'!$A12="","",'Resumo por Dia'!$H12) | G12: =IF('Resumo por Dia'!$A12="","",'Resumo por Dia'!$N12) | H12: =IF('Resumo por Dia'!$A12="","",'Resumo por Dia'!$B12)
A13: =IF('Resumo por Dia'!$A13="","",'Resumo por Dia'!$A13) | B13: =IF('Resumo por Dia'!$A13="","",'Resumo por Dia'!$D13) | C13: =IF('Resumo por Dia'!$A13="","",'Resumo por Dia'!$E13) | D13: =IF('Resumo por Dia'!$A13="","",'Resumo por Dia'!$F13) | E13: =IF('Resumo por Dia'!$A13="","",'Resumo por Dia'!$G13) | F13: =IF('Resumo por Dia'!$A13="","",'Resumo por Dia'!$H13) | G13: =IF('Resumo por Dia'!$A13="","",'Resumo por Dia'!$N13) | H13: =IF('Resumo por Dia'!$A13="","",'Resumo por Dia'!$B13)
A14: =IF('Resumo por Dia'!$A14="","",'Resumo por Dia'!$A14) | B14: =IF('Resumo por Dia'!$A14="","",'Resumo por Dia'!$D14) | C14: =IF('Resumo por Dia'!$A14="","",'Resumo por Dia'!$E14) | D14: =IF('Resumo por Dia'!$A14="","",'Resumo por Dia'!$F14) | E14: =IF('Resumo por Dia'!$A14="","",'Resumo por Dia'!$G14) | F14: =IF('Resumo por Dia'!$A14="","",'Resumo por Dia'!$H14) | G14: =IF('Resumo por Dia'!$A14="","",'Resumo por Dia'!$N14) | H14: =IF('Resumo por Dia'!$A14="","",'Resumo por Dia'!$B14)
A15: =IF('Resumo por Dia'!$A15="","",'Resumo por Dia'!$A15) | B15: =IF('Resumo por Dia'!$A15="","",'Resumo por Dia'!$D15) | C15: =IF('Resumo por Dia'!$A15="","",'Resumo por Dia'!$E15) | D15: =IF('Resumo por Dia'!$A15="","",'Resumo por Dia'!$F15) | E15: =IF('Resumo por Dia'!$A15="","",'Resumo por Dia'!$G15) | F15: =IF('Resumo por Dia'!$A15="","",'Resumo por Dia'!$H15) | G15: =IF('Resumo por Dia'!$A15="","",'Resumo por Dia'!$N15) | H15: =IF('Resumo por Dia'!$A15="","",'Resumo por Dia'!$B15)
... A203: =IF('Resumo por Dia'!$A203="","",'Resumo por Dia'!$A203) | B203: =IF('Resumo por Dia'!$A203="","",'Resumo por Dia'!$D203) | C203: =IF('Resumo por Dia'!$A203="","",'Resumo por Dia'!$E203) | D203: =IF('Resumo por Dia'!$A203="","",'Resumo por Dia'!$F203) | E203: =IF('Resumo por Dia'!$A203="","",'Resumo por Dia'!$G203) | F203: =IF('Resumo por Dia'!$A203="","",'Resumo por Dia'!$H203) | G203: =IF('Resumo por Dia'!$A203="","",'Resumo por Dia'!$N203) | H203: =IF('Resumo por Dia'!$A203="","",'Resumo por Dia'!$B203)

Sheet Evolução Mensal
A1: FECHAMENTO MENSAL
A2: Espelho da aba Resumo por Mês — uma linha por mês, escrita pelo app.
A3: Mês | B3: Dias | C3: Consumo (L) | D3: Horas | E3: L/h | F3: Produção (t) | G3: L/Ton | H3: Viagens | I3: Manut.
A4: =IF('Resumo por Mês'!$A4="","",'Resumo por Mês'!$A4) | B4: =IF('Resumo por Mês'!$A4="","",'Resumo por Mês'!$B4) | C4: =IF('Resumo por Mês'!$A4="","",'Resumo por Mês'!$E4) | D4: =IF('Resumo por Mês'!$A4="","",'Resumo por Mês'!$F4) | E4: =IF('Resumo por Mês'!$A4="","",'Resumo por Mês'!$G4) | F4: =IF('Resumo por Mês'!$A4="","",'Resumo por Mês'!$H4) | G4: =IF('Resumo por Mês'!$A4="","",'Resumo por Mês'!$I4) | H4: =IF('Resumo por Mês'!$A4="","",'Resumo por Mês'!$O4) | I4: =IF('Resumo por Mês'!$A4="","",'Resumo por Mês'!$P4)
A5: =IF('Resumo por Mês'!$A5="","",'Resumo por Mês'!$A5) | B5: =IF('Resumo por Mês'!$A5="","",'Resumo por Mês'!$B5) | C5: =IF('Resumo por Mês'!$A5="","",'Resumo por Mês'!$E5) | D5: =IF('Resumo por Mês'!$A5="","",'Resumo por Mês'!$F5) | E5: =IF('Resumo por Mês'!$A5="","",'Resumo por Mês'!$G5) | F5: =IF('Resumo por Mês'!$A5="","",'Resumo por Mês'!$H5) | G5: =IF('Resumo por Mês'!$A5="","",'Resumo por Mês'!$I5) | H5: =IF('Resumo por Mês'!$A5="","",'Resumo por Mês'!$O5) | I5: =IF('Resumo por Mês'!$A5="","",'Resumo por Mês'!$P5)
A6: =IF('Resumo por Mês'!$A6="","",'Resumo por Mês'!$A6) | B6: =IF('Resumo por Mês'!$A6="","",'Resumo por Mês'!$B6) | C6: =IF('Resumo por Mês'!$A6="","",'Resumo por Mês'!$E6) | D6: =IF('Resumo por Mês'!$A6="","",'Resumo por Mês'!$F6) | E6: =IF('Resumo por Mês'!$A6="","",'Resumo por Mês'!$G6) | F6: =IF('Resumo por Mês'!$A6="","",'Resumo por Mês'!$H6) | G6: =IF('Resumo por Mês'!$A6="","",'Resumo por Mês'!$I6) | H6: =IF('Resumo por Mês'!$A6="","",'Resumo por Mês'!$O6) | I6: =IF('Resumo por Mês'!$A6="","",'Resumo por Mês'!$P6)
A7: =IF('Resumo por Mês'!$A7="","",'Resumo por Mês'!$A7) | B7: =IF('Resumo por Mês'!$A7="","",'Resumo por Mês'!$B7) | C7: =IF('Resumo por Mês'!$A7="","",'Resumo por Mês'!$E7) | D7: =IF('Resumo por Mês'!$A7="","",'Resumo por Mês'!$F7) | E7: =IF('Resumo por Mês'!$A7="","",'Resumo por Mês'!$G7) | F7: =IF('Resumo por Mês'!$A7="","",'Resumo por Mês'!$H7) | G7: =IF('Resumo por Mês'!$A7="","",'Resumo por Mês'!$I7) | H7: =IF('Resumo por Mês'!$A7="","",'Resumo por Mês'!$O7) | I7: =IF('Resumo por Mês'!$A7="","",'Resumo por Mês'!$P7)
A8: =IF('Resumo por Mês'!$A8="","",'Resumo por Mês'!$A8) | B8: =IF('Resumo por Mês'!$A8="","",'Resumo por Mês'!$B8) | C8: =IF('Resumo por Mês'!$A8="","",'Resumo por Mês'!$E8) | D8: =IF('Resumo por Mês'!$A8="","",'Resumo por Mês'!$F8) | E8: =IF('Resumo por Mês'!$A8="","",'Resumo por Mês'!$G8) | F8: =IF('Resumo por Mês'!$A8="","",'Resumo por Mês'!$H8) | G8: =IF('Resumo por Mês'!$A8="","",'Resumo por Mês'!$I8) | H8: =IF('Resumo por Mês'!$A8="","",'Resumo por Mês'!$O8) | I8: =IF('Resumo por Mês'!$A8="","",'Resumo por Mês'!$P8)
A9: =IF('Resumo por Mês'!$A9="","",'Resumo por Mês'!$A9) | B9: =IF('Resumo por Mês'!$A9="","",'Resumo por Mês'!$B9) | C9: =IF('Resumo por Mês'!$A9="","",'Resumo por Mês'!$E9) | D9: =IF('Resumo por Mês'!$A9="","",'Resumo por Mês'!$F9) | E9: =IF('Resumo por Mês'!$A9="","",'Resumo por Mês'!$G9) | F9: =IF('Resumo por Mês'!$A9="","",'Resumo por Mês'!$H9) | G9: =IF('Resumo por Mês'!$A9="","",'Resumo por Mês'!$I9) | H9: =IF('Resumo por Mês'!$A9="","",'Resumo por Mês'!$O9) | I9: =IF('Resumo por Mês'!$A9="","",'Resumo por Mês'!$P9)
A10: =IF('Resumo por Mês'!$A10="","",'Resumo por Mês'!$A10) | B10: =IF('Resumo por Mês'!$A10="","",'Resumo por Mês'!$B10) | C10: =IF('Resumo por Mês'!$A10="","",'Resumo por Mês'!$E10) | D10: =IF('Resumo por Mês'!$A10="","",'Resumo por Mês'!$F10) | E10: =IF('Resumo por Mês'!$A10="","",'Resumo por Mês'!$G10) | F10: =IF('Resumo por Mês'!$A10="","",'Resumo por Mês'!$H10) | G10: =IF('Resumo por Mês'!$A10="","",'Resumo por Mês'!$I10) | H10: =IF('Resumo por Mês'!$A10="","",'Resumo por Mês'!$O10) | I10: =IF('Resumo por Mês'!$A10="","",'Resumo por Mês'!$P10)
A11: =IF('Resumo por Mês'!$A11="","",'Resumo por Mês'!$A11) | B11: =IF('Resumo por Mês'!$A11="","",'Resumo por Mês'!$B11) | C11: =IF('Resumo por Mês'!$A11="","",'Resumo por Mês'!$E11) | D11: =IF('Resumo por Mês'!$A11="","",'Resumo por Mês'!$F11) | E11: =IF('Resumo por Mês'!$A11="","",'Resumo por Mês'!$G11) | F11: =IF('Resumo por Mês'!$A11="","",'Resumo por Mês'!$H11) | G11: =IF('Resumo por Mês'!$A11="","",'Resumo por Mês'!$I11) | H11: =IF('Resumo por Mês'!$A11="","",'Resumo por Mês'!$O11) | I11: =IF('Resumo por Mês'!$A11="","",'Resumo por Mês'!$P11)
A12: =IF('Resumo por Mês'!$A12="","",'Resumo por Mês'!$A12) | B12: =IF('Resumo por Mês'!$A12="","",'Resumo por Mês'!$B12) | C12: =IF('Resumo por Mês'!$A12="","",'Resumo por Mês'!$E12) | D12: =IF('Resumo por Mês'!$A12="","",'Resumo por Mês'!$F12) | E12: =IF('Resumo por Mês'!$A12="","",'Resumo por Mês'!$G12) | F12: =IF('Resumo por Mês'!$A12="","",'Resumo por Mês'!$H12) | G12: =IF('Resumo por Mês'!$A12="","",'Resumo por Mês'!$I12) | H12: =IF('Resumo por Mês'!$A12="","",'Resumo por Mês'!$O12) | I12: =IF('Resumo por Mês'!$A12="","",'Resumo por Mês'!$P12)
A13: =IF('Resumo por Mês'!$A13="","",'Resumo por Mês'!$A13) | B13: =IF('Resumo por Mês'!$A13="","",'Resumo por Mês'!$B13) | C13: =IF('Resumo por Mês'!$A13="","",'Resumo por Mês'!$E13) | D13: =IF('Resumo por Mês'!$A13="","",'Resumo por Mês'!$F13) | E13: =IF('Resumo por Mês'!$A13="","",'Resumo por Mês'!$G13) | F13: =IF('Resumo por Mês'!$A13="","",'Resumo por Mês'!$H13) | G13: =IF('Resumo por Mês'!$A13="","",'Resumo por Mês'!$I13) | H13: =IF('Resumo por Mês'!$A13="","",'Resumo por Mês'!$O13) | I13: =IF('Resumo por Mês'!$A13="","",'Resumo por Mês'!$P13)
A14: =IF('Resumo por Mês'!$A14="","",'Resumo por Mês'!$A14) | B14: =IF('Resumo por Mês'!$A14="","",'Resumo por Mês'!$B14) | C14: =IF('Resumo por Mês'!$A14="","",'Resumo por Mês'!$E14) | D14: =IF('Resumo por Mês'!$A14="","",'Resumo por Mês'!$F14) | E14: =IF('Resumo por Mês'!$A14="","",'Resumo por Mês'!$G14) | F14: =IF('Resumo por Mês'!$A14="","",'Resumo por Mês'!$H14) | G14: =IF('Resumo por Mês'!$A14="","",'Resumo por Mês'!$I14) | H14: =IF('Resumo por Mês'!$A14="","",'Resumo por Mês'!$O14) | I14: =IF('Resumo por Mês'!$A14="","",'Resumo por Mês'!$P14)
A15: =IF('Resumo por Mês'!$A15="","",'Resumo por Mês'!$A15) | B15: =IF('Resumo por Mês'!$A15="","",'Resumo por Mês'!$B15) | C15: =IF('Resumo por Mês'!$A15="","",'Resumo por Mês'!$E15) | D15: =IF('Resumo por Mês'!$A15="","",'Resumo por Mês'!$F15) | E15: =IF('Resumo por Mês'!$A15="","",'Resumo por Mês'!$G15) | F15: =IF('Resumo por Mês'!$A15="","",'Resumo por Mês'!$H15) | G15: =IF('Resumo por Mês'!$A15="","",'Resumo por Mês'!$I15) | H15: =IF('Resumo por Mês'!$A15="","",'Resumo por Mês'!$O15) | I15: =IF('Resumo por Mês'!$A15="","",'Resumo por Mês'!$P15)
... A39: =IF('Resumo por Mês'!$A39="","",'Resumo por Mês'!$A39) | B39: =IF('Resumo por Mês'!$A39="","",'Resumo por Mês'!$B39) | C39: =IF('Resumo por Mês'!$A39="","",'Resumo por Mês'!$E39) | D39: =IF('Resumo por Mês'!$A39="","",'Resumo por Mês'!$F39) | E39: =IF('Resumo por Mês'!$A39="","",'Resumo por Mês'!$G39) | F39: =IF('Resumo por Mês'!$A39="","",'Resumo por Mês'!$H39) | G39: =IF('Resumo por Mês'!$A39="","",'Resumo por Mês'!$I39) | H39: =IF('Resumo por Mês'!$A39="","",'Resumo por Mês'!$O39) | I39: =IF('Resumo por Mês'!$A39="","",'Resumo por Mês'!$P39)

Sheet Frota e Manutenção
A1: FROTA E MANUTENÇÃO
A2: Situação atual de cada equipamento. Fonte: abas Equipamentos e Manutenções.
A3: Equipamento | B3: Tipo | C3: Situação | D3: Horímetro atual | E3: KM atual | F3: Manutenções no período | G3: Última manutenção
A4: =IF(Equipamentos!$A4="","",Equipamentos!$A4) | B4: =IF(Equipamentos!$A4="","",Equipamentos!$B4) | C4: =IF(Equipamentos!$A4="","",Equipamentos!$D4) | D4: =IF(Equipamentos!$A4="","",Equipamentos!$E4) | E4: =IF(Equipamentos!$A4="","",Equipamentos!$F4) | F4: =IF(Equipamentos!$A4="","",COUNTIFS(Manutenções!$B$4:$B$500,$A4,Manutenções!$A$4:$A$500,">="&Diretoria!$B$4,Manutenções!$A$4:$A$500,"<="&Diretoria!$D$4)) | G4: =IF(Equipamentos!$A4="","",IF(SUMPRODUCT(MAX((Manutenções!$B$4:$B$500=$A4)*(Manutenções!$A$4:$A$500)))=0,"—",SUMPRODUCT(MAX((Manutenções!$B$4:$B$500=$A4)*(Manutenções!$A$4:$A$500)))))
A5: =IF(Equipamentos!$A5="","",Equipamentos!$A5) | B5: =IF(Equipamentos!$A5="","",Equipamentos!$B5) | C5: =IF(Equipamentos!$A5="","",Equipamentos!$D5) | D5: =IF(Equipamentos!$A5="","",Equipamentos!$E5) | E5: =IF(Equipamentos!$A5="","",Equipamentos!$F5) | F5: =IF(Equipamentos!$A5="","",COUNTIFS(Manutenções!$B$4:$B$500,$A5,Manutenções!$A$4:$A$500,">="&Diretoria!$B$4,Manutenções!$A$4:$A$500,"<="&Diretoria!$D$4)) | G5: =IF(Equipamentos!$A5="","",IF(SUMPRODUCT(MAX((Manutenções!$B$4:$B$500=$A5)*(Manutenções!$A$4:$A$500)))=0,"—",SUMPRODUCT(MAX((Manutenções!$B$4:$B$500=$A5)*(Manutenções!$A$4:$A$500)))))
A6: =IF(Equipamentos!$A6="","",Equipamentos!$A6) | B6: =IF(Equipamentos!$A6="","",Equipamentos!$B6) | C6: =IF(Equipamentos!$A6="","",Equipamentos!$D6) | D6: =IF(Equipamentos!$A6="","",Equipamentos!$E6) | E6: =IF(Equipamentos!$A6="","",Equipamentos!$F6) | F6: =IF(Equipamentos!$A6="","",COUNTIFS(Manutenções!$B$4:$B$500,$A6,Manutenções!$A$4:$A$500,">="&Diretoria!$B$4,Manutenções!$A$4:$A$500,"<="&Diretoria!$D$4)) | G6: =IF(Equipamentos!$A6="","",IF(SUMPRODUCT(MAX((Manutenções!$B$4:$B$500=$A6)*(Manutenções!$A$4:$A$500)))=0,"—",SUMPRODUCT(MAX((Manutenções!$B$4:$B$500=$A6)*(Manutenções!$A$4:$A$500)))))
